<?xml version="1.0" encoding="utf-8"?>
<robot name="amr_bot" xmlns:xacro="http://ros.org/wiki/xacro">

  <!-- <xacro:property name="wheel_radius" value="0.0767"/>
    <xacro:property name="wheel_width" value="0.035"/> -->

  <link name="base_footprint"></link>
  <joint name="joint_0" type="fixed">
    <parent link="base_footprint" />
    <child link="base_link" />
  </joint>

  <link name="base_link">
    <inertial>
      <origin xyz="0.154134791457833 0.128335370253244 -0.0303964618780423" rpy="0 0 0" />
      <mass value="17.7243278923098" />
      <inertia ixx="0.151725562910189" ixy="0" ixz="0" iyy="0.209426046443263" iyz="0" izz="0.10643501504363" />
    </inertial>
    <visual>
      <origin xyz="0 -0.031 0" rpy="0 0 0" />
      <material name="blue">
        <color rgba="0 0 1 1" />
      </material>
      <geometry>
        <mesh filename="package://amr_sim_ros2/meshes/base_link.STL" />
      </geometry>
    </visual>
    <collision>
      <origin xyz="0.075 0 0.14" rpy="0 0 0" />
      <geometry>
        <!-- <box size="0.68 0.50 0.27"/> -->
        <box size="0.68 0.40 0.27" />
      </geometry>
    </collision>
  </link>

  <joint name="right_joint" type="revolute">
    <limit upper="3.1415" lower="-3.1415" effort="30" velocity="5.0" />
    <origin xyz="0.064918 0.2 0.0767" rpy="0 0 0" />
    <parent link="base_link" />
    <child link="wheel_r" />
    <axis xyz="0 -1 0" />
  </joint>

  <link name="wheel_r">
    <inertial>
      <mass value="1.1541" />
      <inertia ixx="0.0029866" ixy="0" ixz="0" iyy="0.0016967" iyz="0" izz="0.0016788" />
    </inertial>
    <collision>
      <origin xyz="0 0.042 0" rpy="1.57 0 0" />
      <geometry>
        <cylinder radius="0.0767" length="0.035" />
      </geometry>
    </collision>
    <visual>
      <origin xyz="0 0 0" rpy="0 0 1.57" />
      <material name="red">
        <color rgba="1 0 0 1" />
      </material>
      <geometry>
        <mesh filename="package://amr_sim_ros2/meshes/Wheel_2.STL" />
      </geometry>
    </visual>
  </link>

  <joint name="left_joint" type="continuous">
    <origin xyz="0.064918 -0.2 0.0767" rpy="0 0 3.14" />
    <parent link="base_link" />
    <child link="wheel_l" />
    <axis xyz="0 1 0" />
  </joint>

  <link name="wheel_l">
    <inertial>
      <mass value="1.1541" />
      <inertia ixx="0.0029866" ixy="0" ixz="0" iyy="0.0016967" iyz="0" izz="0.0016788" />
    </inertial>
    <collision>
      <origin xyz="0 0.042 0" rpy="1.57 0 0" />
      <geometry>
        <cylinder radius="0.0767" length="0.035" />
      </geometry>
    </collision>
    <visual>
      <origin xyz="0 0 0" rpy="0 0 1.57" />
      <material name="red">
        <color rgba="1 0 0 1" />
      </material>
      <geometry>
        <mesh filename="package://amr_sim_ros2/meshes/Wheel_2.STL" />
      </geometry>
    </visual>
  </link>

  <joint name="imu_joint" type="fixed">
    <origin xyz="0.0 0 0.31" rpy="0 0 0" />
    <parent link="base_link" />
    <child link="imu_link" />
  </joint>

  <link name="imu_link"></link>

  <joint name="lidar_joint" type="fixed">
    <origin xyz="-0.15 0 0.31" rpy="0 0 0" />
    <parent link="base_link" />
    <child link="lidar_link" />
  </joint>

  <link name="lidar_link">
    <collision>
      <origin xyz="0 0 0" rpy="0 0 0" />
      <geometry>
        <cylinder radius="0.06" length="0.080" />
      </geometry>
    </collision>
    <visual>
      <origin xyz="0 0 0" rpy="0 0 0" />
      <material name="green">
        <color rgba="0 1 0 1" />
      </material>
      <geometry>
        <cylinder radius="0.06" length="0.080" />
      </geometry>
    </visual>
  </link>

  <gazebo>
    <plugin name="differential_drive_controller" filename="libgazebo_ros_diff_drive.so">
      <updateRate>40</updateRate>
      <!-- Name of left joint, defaults to `left_joint` -->
      <leftJoint>left_joint</leftJoint>
      <!-- Name of right joint, defaults to `right_joint` -->
      <rightJoint>right_joint</rightJoint>
      <!-- The distance from the center of one wheel to the other, in meters, defaults to 0.34 m -->
      <wheelSeparation>0.4</wheelSeparation>
      <!-- Diameter of the wheels, in meters, defaults to 0.15 m -->
      <wheelDiameter>0.1534</wheelDiameter>
      <!-- Wheel acceleration, in rad/s^2, defaults to 0.0 rad/s^2 -->
      <wheelAcceleration>1.0</wheelAcceleration>
      <!-- Maximum torque which the wheels can produce, in Nm, defaults to 5 Nm -->
      <wheelTorque>20</wheelTorque>
      <!-- Topic to receive geometry_msgs/Twist message commands, defaults to `cmd_vel` -->
      <commandTopic>cmd_vel</commandTopic>
      <!-- Topic to publish nav_msgs/Odometry messages, defaults to `odom` -->
      <odometryTopic>odom</odometryTopic>
      <!-- Odometry frame, defaults to `odom` -->
      <odometryFrame>odom</odometryFrame>
      <!-- Robot frame to calculate odometry from, defaults to `base_footprint` -->
      <robotBaseFrame>base_footprint</robotBaseFrame>
      <!-- Odometry source, 0 for ENCODER, 1 for WORLD, defaults to WORLD -->
      <odometrySource>1</odometrySource>
      <!-- Set to true to publish transforms for the wheel links, defaults to false -->
      <publishWheelTF>false</publishWheelTF>
      <!-- Set to true to publish transforms for the odometry, defaults to true -->
      <publishOdom>false</publishOdom>
      <!-- Set to true to publish sensor_msgs/JointState on /joint_states for the wheel joints, defaults to false -->
      <publishWheelJointState>false</publishWheelJointState>
      <!-- Set to true to swap right and left wheels, defaults to true -->
      <legacyMode>false</legacyMode>
    </plugin>

    <plugin name="cad_assembly_amr_joint_state" filename="libgazebo_ros_joint_state_publisher.so">
      <ros>
        <remapping>~/out:=joint_states</remapping>
      </ros>
      <update_rate>30</update_rate>
      <joint_name>left_joint</joint_name>
      <joint_name>right_joint</joint_name>
    </plugin>
  </gazebo>

  <gazebo reference="lidar_link">
    <sensor type="gpu_ray" name="head_hokuyo_sensor">
      <pose>0 0 0 0 0 0</pose>
      <visualize>true</visualize>
      <update_rate>40</update_rate>
      <ray>
        <scan>
          <horizontal>
            <samples>720</samples>
            <resolution>1</resolution>
            <min_angle>-1.570796</min_angle>
            <max_angle>1.570796</max_angle>
          </horizontal>
        </scan>
        <range>
          <min>0.10</min>
          <max>30.0</max>
          <resolution>0.01</resolution>
        </range>
        <noise>
          <type>gaussian</type>
          <mean>0.0</mean>
          <stddev>0.01</stddev>
        </noise>
      </ray>
      <plugin name="gazebo_ros_head_hokuyo_controller" filename="libgazebo_ros_gpu_laser.so">
        <topicName>/laser/scan</topicName>
        <frameName>lidar_link</frameName>
      </plugin>
    </sensor>
  </gazebo>

</robot>