<sdf version='1.7'>
  <model name='cad_assembly_amr'>
    <link name='base_footprint'>
      <inertial>
        <pose>0.154135 0.128335 -0.030396 0 -0 0</pose>
        <mass>17.7243</mass>
        <inertia>
          <ixx>0.151726</ixx>
          <ixy>0</ixy>
          <ixz>0</ixz>
          <iyy>0.209426</iyy>
          <iyz>0</iyz>
          <izz>0.106435</izz>
        </inertia>
      </inertial>
      <collision name='base_footprint_fixed_joint_lump__base_link_collision'>
        <pose>0.075 0 0.14 0 -0 0</pose>
        <geometry>
          <box>
            <size>0.68 0.4 0.27</size>
          </box>
        </geometry>
      </collision>
      <collision name='base_footprint_fixed_joint_lump__imu_link_collision_1'>
        <pose>0 0 0.31 0 -0 0</pose>
        <geometry>
          <cylinder>
            <length>0.08</length>
            <radius>0.0767</radius>
          </cylinder>
        </geometry>
      </collision>
      <collision name='base_footprint_fixed_joint_lump__lidar_link_collision_2'>
        <pose>0.35 0 0.31 0 -0 0</pose>
        <geometry>
          <cylinder>
            <length>0.08</length>
            <radius>0.0767</radius>
          </cylinder>
        </geometry>
        <surface>
          <contact>
            <ode/>
          </contact>
          <friction>
            <ode/>
          </friction>
        </surface>
      </collision>
      <visual name='base_footprint_fixed_joint_lump__base_link_visual'>
        <pose>0 -0.031 0 0 -0 0</pose>
        <geometry>
          <mesh>
            <scale>1 1 1</scale>
            <uri>model://cad_assembly_amr/meshes/base_link.STL</uri>
          </mesh>
        </geometry>
      </visual>
      <visual name='base_footprint_fixed_joint_lump__imu_link_visual_1'>
        <pose>0 0 0.31 0 -0 0</pose>
        <geometry>
          <cylinder>
            <length>0.08</length>
            <radius>0.0767</radius>
          </cylinder>
        </geometry>
      </visual>
      <visual name='base_footprint_fixed_joint_lump__lidar_link_visual_2'>
        <pose>0.35 0 0.31 0 -0 0</pose>
        <geometry>
          <cylinder>
            <length>0.08</length>
            <radius>0.0767</radius>
          </cylinder>
        </geometry>
      </visual>
      <sensor name='head_hokuyo_sensor' type='gpu_ray'>
        <visualize>1</visualize>
        <update_rate>40</update_rate>
        <ray>
          <scan>
            <horizontal>
              <samples>720</samples>
              <resolution>1</resolution>
              <min_angle>-1.5708</min_angle>
              <max_angle>1.5708</max_angle>
            </horizontal>
          </scan>
          <range>
            <min>0.1</min>
            <max>30</max>
            <resolution>0.01</resolution>
          </range>
          <noise>
            <type>gaussian</type>
            <mean>0</mean>
            <stddev>0.01</stddev>
          </noise>
        </ray>
        <plugin name='gazebo_ros_head_hokuyo_controller' filename='libgazebo_ros_gpu_laser.so'>
          <topicName>/laser/scan</topicName>
          <frameName>lidar_link</frameName>
        </plugin>
        <pose>0.35 0 0.31 0 -0 0</pose>
      </sensor>
    </link>
    <joint name='left_joint' type='revolute'>
      <pose relative_to='base_footprint'>0.064918 -0.2 0.0767 0 -0 3.14</pose>
      <parent>base_footprint</parent>
      <child>wheel_l</child>
      <axis>
        <xyz>0 1 0</xyz>
        <limit>
          <lower>-1e+16</lower>
          <upper>1e+16</upper>
        </limit>
        <dynamics>
          <spring_reference>0</spring_reference>
          <spring_stiffness>0</spring_stiffness>
        </dynamics>
      </axis>
    </joint>
    <link name='wheel_l'>
      <pose relative_to='left_joint'>0 0 0 0 -0 0</pose>
      <inertial>
        <pose>0 0 0 0 -0 0</pose>
        <mass>1.1541</mass>
        <inertia>
          <ixx>0.0029866</ixx>
          <ixy>0</ixy>
          <ixz>0</ixz>
          <iyy>0.0016967</iyy>
          <iyz>0</iyz>
          <izz>0.0016788</izz>
        </inertia>
      </inertial>
      <collision name='wheel_l_collision'>
        <pose>0 0.042 0 1.57 -0 0</pose>
        <geometry>
          <cylinder>
            <length>0.035</length>
            <radius>0.0767</radius>
          </cylinder>
        </geometry>
      </collision>
      <visual name='wheel_l_visual'>
        <pose>0 0 0 0 -0 1.57</pose>
        <geometry>
          <mesh>
            <scale>1 1 1</scale>
            <uri>model://cad_assembly_amr/meshes/Wheel_2.STL</uri>
          </mesh>
        </geometry>
      </visual>
    </link>
    <joint name='right_joint' type='revolute'>
      <pose relative_to='base_footprint'>0.064918 0.2 0.0767 0 -0 0</pose>
      <parent>base_footprint</parent>
      <child>wheel_r</child>
      <axis>
        <xyz>0 -1 0</xyz>
        <limit>
          <lower>-3.1415</lower>
          <upper>3.1415</upper>
          <effort>30</effort>
          <velocity>5</velocity>
        </limit>
        <dynamics>
          <spring_reference>0</spring_reference>
          <spring_stiffness>0</spring_stiffness>
        </dynamics>
      </axis>
    </joint>
    <link name='wheel_r'>
      <pose relative_to='right_joint'>0 0 0 0 -0 0</pose>
      <inertial>
        <pose>0 0 0 0 -0 0</pose>
        <mass>1.1541</mass>
        <inertia>
          <ixx>0.0029866</ixx>
          <ixy>0</ixy>
          <ixz>0</ixz>
          <iyy>0.0016967</iyy>
          <iyz>0</iyz>
          <izz>0.0016788</izz>
        </inertia>
      </inertial>
      <collision name='wheel_r_collision'>
        <pose>0 0.042 0 1.57 -0 0</pose>
        <geometry>
          <cylinder>
            <length>0.035</length>
            <radius>0.0767</radius>
          </cylinder>
        </geometry>
      </collision>
      <visual name='wheel_r_visual'>
        <pose>0 0 0 0 -0 1.57</pose>
        <geometry>
          <mesh>
            <scale>1 1 1</scale>
            <uri>model://cad_assembly_amr/meshes/Wheel_2.STL</uri>
          </mesh>
        </geometry>
      </visual>
    </link>
    <static>0</static>
    <plugin name='differential_drive_controller' filename='libgazebo_ros_diff_drive.so'>
      <updateRate>40</updateRate>
      <leftJoint>left_joint</leftJoint>
      <rightJoint>right_joint</rightJoint>
      <wheelSeparation>0.4</wheelSeparation>
      <wheelDiameter>0.1534</wheelDiameter>
      <wheelAcceleration>1.0</wheelAcceleration>
      <wheelTorque>20</wheelTorque>
      <commandTopic>cmd_vel</commandTopic>
      <odometryTopic>odom</odometryTopic>
      <odometryFrame>odom</odometryFrame>
      <robotBaseFrame>base_footprint</robotBaseFrame>
      <odometrySource>1</odometrySource>
      <publishWheelTF>0</publishWheelTF>
      <publishOdom>0</publishOdom>
      <publishWheelJointState>0</publishWheelJointState>
      <legacyMode>0</legacyMode>
    </plugin>
    <plugin name='cad_assembly_amr_joint_state' filename='libgazebo_ros_joint_state_publisher.so'>
      <ros>
        <remapping>~/out:=joint_states</remapping>
      </ros>
      <update_rate>30</update_rate>
      <joint_name>left_joint</joint_name>
      <joint_name>right_joint</joint_name>
    </plugin>
  </model>
</sdf>
